Workbook

Sheet README
A1: ⚠ Synthetic data — created solely for POC demonstration. Not Transworld data. All suppliers, SKUs, shipments, emails and documents are fictional.
A2: Proof of Concept – Intelligent Inbound Processing & SKU Onboarding
A3: SP Jain MGB Capstone | WMS Team A – Inbound & SKU Intelligence | Illustrative scenario for Transworld Group (no company data used)
A5: Purpose | B5: Demonstrate how the proposed AI-assisted inbound process would work if Transworld data and system access were available. Every record in this workbook is synthetic.
A6: Story | B6: Inbound email → capture attachments → identify relevant documents → classify → extract → normalise & validate → compare SKUs with WMS Item Master → Existing / Potential New / Ambiguous → confidence score → route uncertain cases to a human → validated structured output.
A7: Period simulated | B7: Two weeks of operations: 1–14 September 2026 (10 working days).
A8: Dataset size | B8: 80 SKUs in Item Master | 8 fictional suppliers | 30 inbound emails / shipments | 79 attachments | 103 line items | 7 exception records (6 seeded + 1 AI false alarm). Majority of shipments are routine; edge cases are the minority.
A9: How to read | B9: Each data sheet separates what was RECEIVED, the GROUND TRUTH (the answer we planted), the SIMULATED AI OUTPUT and the TEST RESULT. KPIs are calculated live by formula from these columns – nothing on the dashboard is typed in.
A10: Colour legend | B10: Column colours: Dark blue = data as received (input) | Green = GROUND TRUTH (known correct answer) | Blue = SIMULATED AI OUTPUT | Orange = TEST RESULT (formula: AI vs ground truth)
A11: Sheets | B11: Suppliers · Item_Master · Inbound_Emails · Documents · Line_Items · Exceptions · Shipment_Summary · Decision_Rules · Test_Cases · KPI_Dashboard · Dashboard_Spec · Stage_Transformation · Slide_Plan
A12: Deliberate AI errors | B12: Small, realistic errors were planted in the simulated AI output so testing is meaningful: 2 document misclassifications (scanned/irrelevant files), 2 extraction errors, 3 SKU decision errors (1 unsafe, 2 conservative), 1 missed exception and 1 false alarm (caused by a mis-read quantity).
A13: Editing | B13: To run a what-if, change any GROUND TRUTH or AI OUTPUT value (green/blue columns); all TEST RESULT columns, Shipment_Summary and KPI_Dashboard update automatically.
A14: Key message | B14: We are NOT claiming this is Transworld's data. We are demonstrating how the proposed solution would work if the required Transworld data and system access were available.

Sheet KPI_Dashboard
A1: ⚠ Synthetic data — created solely for POC demonstration. Not Transworld data. All suppliers, SKUs, shipments, emails and documents are fictional.
A2: STEP 4 – POC Output Dashboard (two-week synthetic run, 1–14 Sep 2026)
A3: Every number below is a live formula over the data sheets – nothing is typed in. Ground truth = planted answer; System output = simulated AI; Accuracy = agreement.
A4: KPI | B4: Ground truth | C4: System output | D4: Result | E4: Definition / formula
A5: A. VOLUME PROCESSED
A6: Inbound emails / shipments | C6: =COUNTA(Shipment_Summary!$A$5:$A$34) -> 30 | E6: Count of shipments in Shipment_Summary
A7: Attachments received | C7: =COUNTA(Documents!$A$5:$A$83) -> 79 | E7: All files attached to the emails, relevant or not
A8: Relevant documents processed | B8: =COUNTIF(Documents!$H$5:$H$83,"Yes") -> 76 | C8: =COUNTIF(Documents!$J$5:$J$83,"<>Not Relevant") -> 77 | E8: GT: documents that are shipment documents. AI: documents the AI treated as relevant
A9: Line items processed | C9: =COUNTA(Line_Items!$A$5:$A$107) -> 103 | E9: All line items extracted from Packing Lists
A10: B. SKU INTELLIGENCE (line level)
A11: Existing SKUs | B11: =COUNTIF(Line_Items!$M$5:$M$107,"Existing") -> 96 | C11: =COUNTIF(Line_Items!$S$5:$S$107,"Existing") -> 96 | E11: Lines classified 'Existing'
A12: Potential new SKUs | B12: =COUNTIF(Line_Items!$M$5:$M$107,"New") -> 4 | C12: =COUNTIF(Line_Items!$S$5:$S$107,"New") -> 3 | E12: Lines classified 'New'
A13: Ambiguous SKUs | B13: =COUNTIF(Line_Items!$M$5:$M$107,"Ambiguous") -> 3 | C13: =COUNTIF(Line_Items!$S$5:$S$107,"Ambiguous") -> 4 | E13: Lines classified 'Ambiguous'
A14: C. VALIDATION & EXCEPTIONS
A15: Validation exceptions (seeded vs flagged) | B15: =COUNTIF(Exceptions!$H$5:$H$11,"Yes") -> 6 | C15: =COUNTIF(Exceptions!$I$5:$I$11,"Yes") -> 6 | E15: Seeded = planted in data; Flagged = raised by AI (includes false alarms)
A16: Exceptions correctly detected | C16: =COUNTIF(Exceptions!$J$5:$J$11,"Detected") -> 5 | E16: Seeded AND flagged
A17: Exceptions missed | C17: =COUNTIF(Exceptions!$J$5:$J$11,"MISSED") -> 1 | E17: Seeded but not flagged
A18: False alarms | C18: =COUNTIF(Exceptions!$J$5:$J$11,"False alarm") -> 1 | E18: Flagged but not seeded
A19: D. ACCURACY (system output vs ground truth)
A20: Document classification accuracy | D20: =SUM(Documents!$M$5:$M$83)/COUNT(Documents!$M$5:$M$83) -> 0.97468354 | E20: Correct classifications / Total attachments
A21: Data extraction accuracy (line level) | D21: =SUM(Line_Items!$AC$5:$AC$107)/COUNT(Line_Items!$AC$5:$AC$107) -> 0.98058252 | E21: Lines with all fields extracted correctly / Total lines
A22: UOM normalisation accuracy | D22: =SUM(Line_Items!$AB$5:$AB$107)/COUNT(Line_Items!$AB$5:$AB$107) -> 1 | E22: Correct normalised UOM / Total lines
A23: SKU matching accuracy | D23: =SUM(Line_Items!$Z$5:$Z$107)/COUNT(Line_Items!$Z$5:$Z$107) -> 0.97087379 | E23: Correct SKU decisions (Existing/New/Ambiguous) / Total SKU decisions
A24: Line validation accuracy | D24: =SUM(Line_Items!$AA$5:$AA$107)/COUNT(Line_Items!$AA$5:$AA$107) -> 0.99029126 | E24: Correct validation status / Total lines
A25: Exception detection rate (recall) | D25: =COUNTIF(Exceptions!$J$5:$J$11,"Detected")/COUNTIF(Exceptions!$H$5:$H$11,"Yes") -> 0.83333333 | E25: Correctly identified exceptions / Total seeded exceptions
A26: Exception precision | D26: =COUNTIF(Exceptions!$J$5:$J$11,"Detected")/COUNTIF(Exceptions!$I$5:$I$11,"Yes") -> 0.83333333 | E26: Correct flags / All flags raised
A27: E. AUTOMATION & HUMAN REVIEW
A28: Lines auto-processed | C28: =COUNTIF(Line_Items!$X$5:$X$107,"Auto-processed") -> 91 | D28: =C28/C9 -> 0.88349515 | E28: Straight-through rate = auto-processed lines / total lines
A29: Lines routed to human (review + new-SKU approval) | C29: =COUNTIF(Line_Items!$X$5:$X$107,"<>Auto-processed") -> 12 | D29: =C29/C9 -> 0.11650485 | E29: Human review share
A30: Shipments auto-processed end-to-end | B30: =COUNTIF(Shipment_Summary!$N$5:$N$34,"Clean") -> 17 | C30: =COUNTIF(Shipment_Summary!$O$5:$O$34,"Auto-processed") -> 15 | E30: GT: shipments that were genuinely clean. AI: shipments with zero human touch
A31: Shipments routed to human review | B31: =COUNTIF(Shipment_Summary!$N$5:$N$34,"Requires review") -> 13 | C31: =COUNTIF(Shipment_Summary!$O$5:$O$34,"Human review") -> 15
A32: Shipment routing accuracy | D32: =(COUNTIF(Shipment_Summary!$P$5:$P$34,"Correct – straight-through")+COUNTIF(Shipment_Summary!$P$5:$P$34,"Correct – caught"))/COUNTA(Shipment_Summary!$A$5:$A$34) -> 0.8 | E32: Correctly routed shipments / Total shipments
A33: Successful automated processing | C33: =COUNTIF(Shipment_Summary!$P$5:$P$34,"Correct – straight-through") -> 13 | E33: Clean shipments correctly auto-processed
A34: CRITICAL: shipments wrongly auto-processed | C34: =COUNTIF(Shipment_Summary!$P$5:$P$34,"MISSED – wrongly auto-processed") -> 2 | E34: Shipments that needed review but passed straight through – drive rule fixes F1/F2
A36: SKU decision matrix (rows = ground truth, columns = system output)
A37: Ground truth ↓ / System → | B37: Existing | C37: New | D37: Ambiguous | E37: Reading
A38: Existing | B38: =COUNTIFS(Line_Items!$M$5:$M$107,"Existing",Line_Items!$S$5:$S$107,"Existing") -> 95 | C38: =COUNTIFS(Line_Items!$M$5:$M$107,"Existing",Line_Items!$S$5:$S$107,"New") -> 0 | D38: =COUNTIFS(Line_Items!$M$5:$M$107,"Existing",Line_Items!$S$5:$S$107,"Ambiguous") -> 1 | E38: Off-diagonal = existing SKU held for review (safe, extra work)
A39: New | B39: =COUNTIFS(Line_Items!$M$5:$M$107,"New",Line_Items!$S$5:$S$107,"Existing") -> 0 | C39: =COUNTIFS(Line_Items!$M$5:$M$107,"New",Line_Items!$S$5:$S$107,"New") -> 3 | D39: =COUNTIFS(Line_Items!$M$5:$M$107,"New",Line_Items!$S$5:$S$107,"Ambiguous") -> 1 | E39: Off-diagonal = new SKU held as ambiguous (safe)
A40: Ambiguous | B40: =COUNTIFS(Line_Items!$M$5:$M$107,"Ambiguous",Line_Items!$S$5:$S$107,"Existing") -> 1 | C40: =COUNTIFS(Line_Items!$M$5:$M$107,"Ambiguous",Line_Items!$S$5:$S$107,"New") -> 0 | D40: =COUNTIFS(Line_Items!$M$5:$M$107,"Ambiguous",Line_Items!$S$5:$S$107,"Ambiguous") -> 2 | E40: 'Existing' column here = UNSAFE auto-match (finding F1)
A43: Shipment routing outcomes
...

Sheet Test_Cases
A1: ⚠ Synthetic data — created solely for POC demonstration. Not Transworld data. All suppliers, SKUs, shipments, emails and documents are fictional.
A2: STEP 3 – Representative End-to-End Test Cases (A–E) + testing feedback
A3: Each column follows one shipment through the proposed process. Values are taken from the synthetic dataset (see Line_Items / Documents).
A4: Stage | B4: TEST A – Clean shipment SYN-SH-001 | C4: TEST B – Potential New SKU SYN-SH-008 | D4: TEST C – Ambiguous SKU SYN-SH-011 | E4: TEST D – Missing quantity SYN-SH-013 | F4: TEST E – Document conflict SYN-SH-023
A5: 1. INPUT | B5: Email SYN-EM-001 from Brightlink Electronics (fictional), 1 Sep. 3 attachments: Packing_List_4401.pdf, CI 7701.pdf, Certificate_of_Origin_001.pdf. | C5: Email SYN-EM-008 from Voltix Components (fictional). 3 attachments: Packing List, Commercial Invoice, Certificate of Origin. | D5: Email SYN-EM-011 from Brightlink Electronics (fictional). 3 attachments: packinglist 4411.pdf, CI 7711.pdf, Certificate of Origin. | E5: Email SYN-EM-013 from Crestline Consumer Products (fictional). 2 attachments: Packing List, Commercial Invoice. | F5: Email SYN-EM-023 from Desert Palm Foodstuff (fictional). 3 attachments: Packing List, Invoice, Bill of Entry.
A6: 2. DOCUMENT CLASSIFICATION | B6: PL → Packing List (conf. high); CI → Commercial Invoice; COO → Certificate of Origin. All 3 relevant, all ≥ 80% → auto. | C6: 3 documents classified correctly; all relevant; auto-accepted. | D6: 3 documents classified correctly; all relevant; auto-accepted. | E6: 2 documents classified correctly. Packing List flagged 'Incomplete'. | F6: 3 documents classified correctly; auto-accepted.
A7: 3. DATA EXTRACTION | B7: 4 lines: EL-4105 Bluetooth Speaker ×600 | EL-4230 LED Strip ×150 | EL-4220 Desk Lamp ×500 | EL-4110 Earbuds Black ×1,000. All PCS, HS, origin China, weights captured. | C7: 4 lines incl. EL-7810 'USB-C Hub 7-in-1 Aluminium' ×300 PCS, HS 8471.80, origin Malaysia, 33.0 kg. | D7: 4 lines incl. 'EL-400I' 'Wireless Router' ×200 PCS, HS 8517.62, China, 240 kg. | E7: 3 lines. Line 2: CG-3210 Hair Dryer 1800W – Quantity field BLANK (weight 168 kg present). Invoice shows 240. | F7: 3 lines. Line 1: PK-6501 Bottled Water 24x500ml – Packing List qty 500 CTN; Invoice qty 550 CTN.
A8: 4. VALIDATION | B8: All mandatory fields present. PL = CI on qty, HS, origin, weight. → VALID. | C8: All fields present; PL = CI. → VALID. | D8: All fields present; PL = CI. → VALID (the issue is identity, not data). | E8: Mandatory field check → FAILED. Missing field: Quantity (line SYN-LN-044). | F8: Cross-document check → CONFLICT. Field: Quantity. Source 1: Packing List = 500. Source 2: Invoice = 550.
A9: 5. WMS ITEM MASTER LOOKUP | B9: All 4 codes found; descriptions match master exactly. | C9: EL-7810 not in master. Closest description: AC-2201 USB-C Cable (41% similar) – not a credible match. | D9: EL-400I not in master. Nearest codes: EL-4001 (1 character: letter 'I' vs digit '1'). Description 'Wireless Router' fits EL-4001 (AX1800) AND EL-4011 (AX3000). | E9: CG-3210 found – exact match. | F9: PK-6501 found – exact match.
A10: 6. MATCH RESULT | B10: 4 × EXISTING SKU. | C10: POTENTIAL NEW SKU. Draft created: EL-7810 | USB-C Hub 7-in-1 Aluminium | Electronics | PCS | HS 8471.80 | Malaysia | SUP-006 | 0.11 kg/unit | Status: Pending approval. | D10: AMBIGUOUS – two plausible candidates; not auto-matched. | E10: EXISTING SKU (identity fine) – but data incomplete. | F10: EXISTING SKU (identity fine) – but data conflicting.
A11: 7. CONFIDENCE SCORE | B11: 95%, 99%, 95%, 98% – all above 90% threshold. | C11: 92% confidence that this is a genuinely new item. | D11: 71% – below 90% threshold. Reason: potential character-level mismatch between extracted SKU and WMS Item Master. | E11: SKU match 97%; shipment blocked by validation failure. | F11: SKU match 95%; shipment blocked by validation conflict.
A12: 8. DECISION | B12: AUTO-PROCESS – no human touch needed. | C12: ROUTE TO HUMAN APPROVAL (new SKUs are never created automatically). Other 3 lines auto-processed. | D12: ROUTE TO HUMAN REVIEW. Other 3 lines auto-processed. | E12: EXCEPTION RAISED – hold line; request corrected Packing List or confirm quantity. | F12: EXCEPTION RAISED – hold line; do not guess which quantity is correct.
A13: 9. HUMAN INTERVENTION | B13: None. | C13: Reviewer sees draft with options APPROVE / EDIT / REJECT. Simulated decision: APPROVE → SKU EL-7810 created in WMS Item Master. | D13: Reviewer compares with PO line and supplier catalogue; selects EL-4001 (AX1800). System learns mapping 'EL-400I' → EL-4001 for this supplier. | E13: Reviewer contacts supplier; corrected quantity 240 confirmed (matches Invoice). Line released. | F13: Reviewer checks PO & supplier: 500 CTN physically shipped; supplier issues credit note for 50 CTN. Line released at 500.
A14: 10. FINAL OUTPUT | B14: Validated record: SYN-SH-001 | 4 lines | all Existing | Status: READY FOR RECEIVING. | C14: Validated record with 4 lines (1 newly onboarded SKU). Status: READY after approval. | D14: Validated record with corrected SKU. Status: READY after review. | E14: Validated record after correction. Status: READY; exception logged in audit trail. | F14: Validated record with resolved quantity. Status: READY; conflict + resolution logged.
A15: KEY MESSAGE | B15: Routine shipments flow straight through. | C15: New items are detected and drafted, but a person stays in control. | D15: The AI knows when it is unsure – it does not force a match. | E15: Incomplete data is stopped, not passed to the warehouse. | F15: The AI cross-checks documents instead of trusting a single one.
A17: TESTING FEEDBACK – what the planted errors taught us
A18: Finding | B18: What happened (synthetic test) | C18: Risk | D18: Proposed fix | E18: Status
A19: F1 – Unsafe auto-match | B19: SYN-SH-021: 'AC-221O' / 'USB-C Cable' auto-corrected to AC-2210 (2m) at 90%, but it could also be AC-2201 (1m). Ground truth = Ambiguous. | C19: High – wrong SKU received into stock | D19: Code correction allowed only when a distinguishing attribute (length, capacity, colour) also matches; otherwise Ambiguous. Or raise threshold for corrected codes to 95%. | E19: Rule update
A20: F2 – Missed weight conflict | B20: SYN-SH-025: Packing List vs Invoice gross weight differs 6.3%; tolerance of 10% let it pass. | C20: Medium – customs / billing discrepancy | D20: Tighten tolerance to 2–3% (to be set with Transworld operations). | E20: Threshold update
A21: F3 – HS code mis-read not caught | B21: SYN-SH-003: HS 8544.42 read as 8544.49; not compared with Item Master. | C21: Medium – customs classification | D21: Add check: extracted HS code vs Item Master HS for existing SKUs. | E21: New validation
A22: F4 – Scanned documents | B22: SYN-SH-012 scanned COO classed as Invoice (66%); SYN-SH-007 qty 1,200 read as 120. Both caught by low confidence / cross-check. | C22: Low – caught, but adds review effort | D22: Add scan-quality check; request digital originals from frequent suppliers. | E22: Process change
A23: F5 – Over-cautious decisions | B23: SYN-SH-009 abbreviated 'BT Spkr' and SYN-SH-022 new mesh kit held as Ambiguous. | C23: Low – safe, extra review | D23: Build supplier-specific abbreviation list from reviewer decisions. | E23: Learning loop

Sheet Item_Master
A1: ⚠ Synthetic data — created solely for POC demonstration. Not Transworld data. All suppliers, SKUs, shipments, emails and documents are fictional.
A2: STEP 1 – Synthetic WMS Item Master (80 SKUs)
A3: Designed with deliberate look-alikes for testing: EL-4001/EL-4011 (routers), AC-2201/AC-2210 (cables 1m/2m), CG-3005/CG-3006 (bottles 750/500ml), EL-4110/EL-4111 (earbuds black/white). 5 SKUs Inactive.
A4: SKU_ID | B4: Product_Description | C4: Category | D4: UOM | E4: HS_Code | F4: Country_of_Origin | G4: Supplier_ID | H4: Supplier_Name | I4: Weight_per_Unit (kg) | J4: Existing_Status | K4: Test_Design_Note
A5: EL-4001 | B5: Wireless Router AX1800 | C5: Electronics | D5: PCS | E5: 8517.62 | F5: China | G5: SUP-001 | H5: =INDEX(Suppliers!$B$5:$B$12,MATCH(G5,Suppliers!$A$5:$A$12,0)) -> Brightlink Electronics Co. (fictional) | I5: 1.2 | J5: Active | K5: Look-alike of EL-4011; target of EL-400I test
A6: EL-4011 | B6: Wireless Router AX3000 | C6: Electronics | D6: PCS | E6: 8517.62 | F6: China | G6: SUP-001 | H6: =INDEX(Suppliers!$B$5:$B$12,MATCH(G6,Suppliers!$A$5:$A$12,0)) -> Brightlink Electronics Co. (fictional) | I6: 1.35 | J6: Active | K6: Look-alike of EL-4001
A7: EL-4020 | B7: Mesh Wi-Fi Node AX1800 (single) | C7: Electronics | D7: PCS | E7: 8517.62 | F7: China | G7: SUP-001 | H7: =INDEX(Suppliers!$B$5:$B$12,MATCH(G7,Suppliers!$A$5:$A$12,0)) -> Brightlink Electronics Co. (fictional) | I7: 0.6 | J7: Active | K7: Resembles new SKU EL-4025 (mesh 3-pack)
A8: EL-4105 | B8: Bluetooth Speaker 10W Portable | C8: Electronics | D8: PCS | E8: 8518.22 | F8: China | G8: SUP-001 | H8: =INDEX(Suppliers!$B$5:$B$12,MATCH(G8,Suppliers!$A$5:$A$12,0)) -> Brightlink Electronics Co. (fictional) | I8: 0.55 | J8: Active
A9: EL-4110 | B9: Wireless Earbuds - True Wireless, Black | C9: Electronics | D9: PCS | E9: 8518.30 | F9: China | G9: SUP-001 | H9: =INDEX(Suppliers!$B$5:$B$12,MATCH(G9,Suppliers!$A$5:$A$12,0)) -> Brightlink Electronics Co. (fictional) | I9: 0.12 | J9: Active | K9: Colour variant of EL-4111
A10: EL-4111 | B10: Wireless Earbuds - True Wireless, White | C10: Electronics | D10: PCS | E10: 8518.30 | F10: China | G10: SUP-001 | H10: =INDEX(Suppliers!$B$5:$B$12,MATCH(G10,Suppliers!$A$5:$A$12,0)) -> Brightlink Electronics Co. (fictional) | I10: 0.12 | J10: Active | K10: Colour variant of EL-4110
A11: EL-4210 | B11: Smart LED Bulb 9W E27 | C11: Electronics | D11: PCS | E11: 8539.52 | F11: China | G11: SUP-001 | H11: =INDEX(Suppliers!$B$5:$B$12,MATCH(G11,Suppliers!$A$5:$A$12,0)) -> Brightlink Electronics Co. (fictional) | I11: 0.08 | J11: Active
A12: EL-4220 | B12: LED Desk Lamp with USB Port | C12: Electronics | D12: PCS | E12: 9405.21 | F12: China | G12: SUP-001 | H12: =INDEX(Suppliers!$B$5:$B$12,MATCH(G12,Suppliers!$A$5:$A$12,0)) -> Brightlink Electronics Co. (fictional) | I12: 0.9 | J12: Active
A13: EL-4301 | B13: Power Bank 10000mAh | C13: Electronics | D13: PCS | E13: 8507.60 | F13: Malaysia | G13: SUP-006 | H13: =INDEX(Suppliers!$B$5:$B$12,MATCH(G13,Suppliers!$A$5:$A$12,0)) -> Voltix Components Sdn Bhd (fictional) | I13: 0.25 | J13: Active
A14: EL-4302 | B14: Power Bank 20000mAh | C14: Electronics | D14: PCS | E14: 8507.60 | F14: Malaysia | G14: SUP-006 | H14: =INDEX(Suppliers!$B$5:$B$12,MATCH(G14,Suppliers!$A$5:$A$12,0)) -> Voltix Components Sdn Bhd (fictional) | I14: 0.42 | J14: Active
A15: EL-4310 | B15: USB-C Wall Charger 20W | C15: Electronics | D15: PCS | E15: 8504.40 | F15: Malaysia | G15: SUP-006 | H15: =INDEX(Suppliers!$B$5:$B$12,MATCH(G15,Suppliers!$A$5:$A$12,0)) -> Voltix Components Sdn Bhd (fictional) | I15: 0.07 | J15: Active
A16: EL-4401 | B16: Wireless Keyboard - Full Size | C16: Electronics | D16: PCS | E16: 8471.60 | F16: Malaysia | G16: SUP-006 | H16: =INDEX(Suppliers!$B$5:$B$12,MATCH(G16,Suppliers!$A$5:$A$12,0)) -> Voltix Components Sdn Bhd (fictional) | I16: 0.65 | J16: Active
A17: EL-4402 | B17: Wireless Optical Mouse | C17: Electronics | D17: PCS | E17: 8471.60 | F17: Malaysia | G17: SUP-006 | H17: =INDEX(Suppliers!$B$5:$B$12,MATCH(G17,Suppliers!$A$5:$A$12,0)) -> Voltix Components Sdn Bhd (fictional) | I17: 0.1 | J17: Active
A18: EL-4410 | B18: HD Webcam 1080p | C18: Electronics | D18: PCS | E18: 8525.89 | F18: Malaysia | G18: SUP-006 | H18: =INDEX(Suppliers!$B$5:$B$12,MATCH(G18,Suppliers!$A$5:$A$12,0)) -> Voltix Components Sdn Bhd (fictional) | I18: 0.18 | J18: Active
A19: EL-4501 | B19: Smartwatch Fitness 1.4in | C19: Electronics | D19: PCS | E19: 8517.62 | F19: China | G19: SUP-001 | H19: =INDEX(Suppliers!$B$5:$B$12,MATCH(G19,Suppliers!$A$5:$A$12,0)) -> Brightlink Electronics Co. (fictional) | I19: 0.09 | J19: Inactive
A20: EL-4230 | B20: LED Strip Light 5m RGB | C20: Electronics | D20: PCS | E20: 9405.42 | F20: China | G20: SUP-001 | H20: =INDEX(Suppliers!$B$5:$B$12,MATCH(G20,Suppliers!$A$5:$A$12,0)) -> Brightlink Electronics Co. (fictional) | I20: 0.3 | J20: Active
A21: AC-2201 | B21: USB-C to USB-C Cable 1m | C21: Accessories | D21: PCS | E21: 8544.42 | F21: Malaysia | G21: SUP-006 | H21: =INDEX(Suppliers!$B$5:$B$12,MATCH(G21,Suppliers!$A$5:$A$12,0)) -> Voltix Components Sdn Bhd (fictional) | I21: 0.05 | J21: Active | K21: Look-alike of AC-2210 (length differs)
A22: AC-2202 | B22: USB-C to Lightning Cable 1m | C22: Accessories | D22: PCS | E22: 8544.42 | F22: Malaysia | G22: SUP-006 | H22: =INDEX(Suppliers!$B$5:$B$12,MATCH(G22,Suppliers!$A$5:$A$12,0)) -> Voltix Components Sdn Bhd (fictional) | I22: 0.05 | J22: Active
A23: AC-2210 | B23: USB-C to USB-C Cable 2m | C23: Accessories | D23: PCS | E23: 8544.42 | F23: Malaysia | G23: SUP-006 | H23: =INDEX(Suppliers!$B$5:$B$12,MATCH(G23,Suppliers!$A$5:$A$12,0)) -> Voltix Components Sdn Bhd (fictional) | I23: 0.08 | J23: Active | K23: Look-alike of AC-2201
A24: AC-2220 | B24: HDMI Cable 2m 4K | C24: Accessories | D24: PCS | E24: 8544.42 | F24: Malaysia | G24: SUP-006 | H24: =INDEX(Suppliers!$B$5:$B$12,MATCH(G24,Suppliers!$A$5:$A$12,0)) -> Voltix Components Sdn Bhd (fictional) | I24: 0.12 | J24: Active
A25: AC-2301 | B25: Phone Case Silicone - Universal 6.1in | C25: Accessories | D25: PCS | E25: 3926.90 | F25: Turkey | G25: SUP-004 | H25: =INDEX(Suppliers!$B$5:$B$12,MATCH(G25,Suppliers!$A$5:$A$12,0)) -> Anka Accessories Trading (fictional) | I25: 0.04 | J25: Active
A26: AC-2310 | B26: Tempered Glass Screen Protector 6.1in | C26: Accessories | D26: PCS | E26: 7007.19 | F26: Turkey | G26: SUP-004 | H26: =INDEX(Suppliers!$B$5:$B$12,MATCH(G26,Suppliers!$A$5:$A$12,0)) -> Anka Accessories Trading (fictional) | I26: 0.03 | J26: Active
A27: AC-2401 | B27: Laptop Sleeve 15in Neoprene | C27: Accessories | D27: PCS | E27: 4202.92 | F27: Turkey | G27: SUP-004 | H27: =INDEX(Suppliers!$B$5:$B$12,MATCH(G27,Suppliers!$A$5:$A$12,0)) -> Anka Accessories Trading (fictional) | I27: 0.3 | J27: Active
A28: AC-2410 | B28: Travel Backpack 25L | C28: Accessories | D28: PCS | E28: 4202.92 | F28: Turkey | G28: SUP-004 | H28: =INDEX(Suppliers!$B$5:$B$12,MATCH(G28,Suppliers!$A$5:$A$12,0)) -> Anka Accessories Trading (fictional) | I28: 0.85 | J28: Active
A29: AC-2501 | B29: Car Phone Holder - Vent Mount | C29: Accessories | D29: PCS | E29: 3926.90 | F29: Turkey | G29: SUP-004 | H29: =INDEX(Suppliers!$B$5:$B$12,MATCH(G29,Suppliers!$A$5:$A$12,0)) -> Anka Accessories Trading (fictional) | I29: 0.09 | J29: Active
A30: AC-2510 | B30: Universal Travel Adapter | C30: Accessories | D30: PCS | E30: 8536.69 | F30: Turkey | G30: SUP-004 | H30: =INDEX(Suppliers!$B$5:$B$12,MATCH(G30,Suppliers!$A$5:$A$12,0)) -> Anka Accessories Trading (fictional) | I30: 0.15 | J30: Active
A31: AC-2601 | B31: Leather Bifold Wallet | C31: Accessories | D31: PCS | E31: 4202.31 | F31: Turkey | G31: SUP-004 | H31: =INDEX(Suppliers!$B$5:$B$12,MATCH(G31,Suppliers!$A$5:$A$12,0)) -> Anka Accessories Trading (fictional) | I31: 0.1 | J31: Active
A32: AC-2610 | B32: Canvas Tote Bag | C32: Accessories | D32: PCS | E32: 4202.22 | F32: Turkey | G32: SUP-004 | H32: =INDEX(Suppliers!$B$5:$B$12,MATCH(G32,Suppliers!$A$5:$A$12,0)) -> Anka Accessories Trading (fictional) | I32: 0.2 | J32: Active
A33: AC-2701 | B33: Sunglasses Polarised Unisex | C33: Accessories | D33: PCS | E33: 9004.10 | F33: Turkey | G33: SUP-004 | H33: =INDEX(Suppliers!$B$5:$B$12,MATCH(G33,Suppliers!$A$5:$A$12,0)) -> Anka Accessories Trading (fictional) | I33: 0.05 | J33: Active
A34: AC-2710 | B34: Watch Strap Silicone 22mm | C34: Accessories | D34: PCS | E34: 9113.90 | F34: Turkey | G34: SUP-004 | H34: =INDEX(Suppliers!$B$5:$B$12,MATCH(G34,Suppliers!$A$5:$A$12,0)) -> Anka Accessories Trading (fictional) | I34: 0.02 | J34: Inactive
A35: AC-2801 | B35: Metal Keychain | C35: Accessories | D35: PCS | E35: 7117.19 | F35: Turkey | G35: SUP-004 | H35: =INDEX(Suppliers!$B$5:$B$12,MATCH(G35,Suppliers!$A$5:$A$12,0)) -> Anka Accessories Trading (fictional) | I35: 0.02 | J35: Active
... A52: HH-5520 | B52: Hand Blender 600W | C52: Household | D52: PCS | E52: 8509.40 | F52: Germany | G52: SUP-008 | H52: =INDEX(Suppliers!$B$5:$B$12,MATCH(G52,Suppliers!$A$5:$A$12,0)) -> Nordkap Home Appliances GmbH (fictional) | I52: 1.1 | J52: Active
A53: CG-3005 | B53: Stainless Steel Water Bottle 750ml | C53: Consumer Goods | D53: PCS | E53: 7323.93 | F53: India | G53: SUP-003 | H53: =INDEX(Suppliers!$B$5:$B$12,MATCH(G53,Suppliers!$A$5:$A$12,0)) -> Crestline Consumer Products Pvt Ltd (fictional) | I53: 0.35 | J53: Active | K53: Look-alike of CG-3006; target of CG-3O05 typo
A54: CG-3006 | B54: Stainless Steel Water Bottle 500ml | C54: Consumer Goods | D54: PCS | E54: 7323.93 | F54: India | G54: SUP-003 | H54: =INDEX(Suppliers!$B$5:$B$12,MATCH(G54,Suppliers!$A$5:$A$12,0)) -> Crestline Consumer Products Pvt Ltd (fictional) | I54: 0.28 | J54: Active | K54: Look-alike of CG-3005
A55: CG-3101 | B55: Yoga Mat 6mm | C55: Consumer Goods | D55: PCS | E55: 9506.91 | F55: India | G55: SUP-003 | H55: =INDEX(Suppliers!$B$5:$B$12,MATCH(G55,Suppliers!$A$5:$A$12,0)) -> Crestline Consumer Products Pvt Ltd (fictional) | I55: 1 | J55: Active
A56: CG-3102 | B56: Dumbbell Pair 5kg | C56: Consumer Goods | D56: SET | E56: 9506.91 | F56: India | G56: SUP-003 | H56: =INDEX(Suppliers!$B$5:$B$12,MATCH(G56,Suppliers!$A$5:$A$12,0)) -> Crestline Consumer Products Pvt Ltd (fictional) | I56: 10.2 | J56: Active
...

Sheet Inbound_Emails
A1: ⚠ Synthetic data — created solely for POC demonstration. Not Transworld data. All suppliers, SKUs, shipments, emails and documents are fictional.
A2: STEP 2a – Table A: Inbound Emails (30 shipments, 1–14 Sep 2026)
A3: One email per shipment. 'Destination' is an illustrative Dubai DC, not an actual Transworld site. Email addresses use the reserved .example domain.
A4: Email_ID | B4: Shipment_ID | C4: Received (date & time) | D4: From | E4: Subject | F4: Supplier_ID | G4: Supplier_Name | H4: Origin_Country | I4: Destination | J4: PO_Number | K4: Attachments_Mentioned | L4: Attachments_Received | M4: Scenario (test design)
A5: SYN-EM-001 | B5: SYN-SH-001 | C5: 2026-09-01 15:03 | D5: shipping@brightlink.example | E5: FW: Shipping documents PO-SYN-7103 | F5: SUP-001 | G5: =INDEX(Suppliers!$B$5:$B$12,MATCH(F5,Suppliers!$A$5:$A$12,0)) -> Brightlink Electronics Co. (fictional) | H5: China | I5: Illustrative DC – Dubai, UAE | J5: PO-SYN-7103 | K5: 3 | L5: =COUNTIF(Documents!$C$5:$C$83,A5) -> 3 | M5: Clean – Test Case A
A6: SYN-EM-002 | B6: SYN-SH-002 | C6: 2026-09-01 14:18 | D6: shipping@crestline.example | E6: Docs attached – PO-SYN-7106 – ETA Dubai | F6: SUP-003 | G6: =INDEX(Suppliers!$B$5:$B$12,MATCH(F6,Suppliers!$A$5:$A$12,0)) -> Crestline Consumer Products Pvt Ltd (fictional) | H6: India | I6: Illustrative DC – Dubai, UAE | J6: PO-SYN-7106 | K6: 2 | L6: =COUNTIF(Documents!$C$5:$C$83,A6) -> 2 | M6: Clean
A7: SYN-EM-003 | B7: SYN-SH-003 | C7: 2026-09-01 09:47 | D7: shipping@voltix.example | E7: ASN / Packing list & invoice for PO PO-SYN-7109 | F7: SUP-006 | G7: =INDEX(Suppliers!$B$5:$B$12,MATCH(F7,Suppliers!$A$5:$A$12,0)) -> Voltix Components Sdn Bhd (fictional) | H7: Malaysia | I7: Illustrative DC – Dubai, UAE | J7: PO-SYN-7109 | K7: 2 | L7: =COUNTIF(Documents!$C$5:$C$83,A7) -> 2 | M7: Clean; UOM 'Pieces' (Case 6)
A8: SYN-EM-004 | B8: SYN-SH-004 | C8: 2026-09-02 16:45 | D8: shipping@brightlink.example | E8: FW: Shipping documents PO-SYN-7112 | F8: SUP-001 | G8: =INDEX(Suppliers!$B$5:$B$12,MATCH(F8,Suppliers!$A$5:$A$12,0)) -> Brightlink Electronics Co. (fictional) | H8: China | I8: Illustrative DC – Dubai, UAE | J8: PO-SYN-7112 | K8: 3 | L8: =COUNTIF(Documents!$C$5:$C$83,A8) -> 3 | M8: Description variation (Case 2)
A9: SYN-EM-005 | B9: SYN-SH-005 | C9: 2026-09-02 09:02 | D9: shipping@desertpalm.example | E9: Docs attached – PO-SYN-7115 – ETA Dubai | F9: SUP-007 | G9: =INDEX(Suppliers!$B$5:$B$12,MATCH(F9,Suppliers!$A$5:$A$12,0)) -> Desert Palm Foodstuff Trading LLC (fictional) | H9: UAE | I9: Illustrative DC – Dubai, UAE | J9: PO-SYN-7115 | K9: 4 | L9: =COUNTIF(Documents!$C$5:$C$83,A9) -> 4 | M9: Clean
A10: SYN-EM-006 | B10: SYN-SH-006 | C10: 2026-09-02 13:22 | D10: shipping@brightlink.example | E10: RE: Dispatch confirmation PO PO-SYN-7118 | F10: SUP-001 | G10: =INDEX(Suppliers!$B$5:$B$12,MATCH(F10,Suppliers!$A$5:$A$12,0)) -> Brightlink Electronics Co. (fictional) | H10: China | I10: Illustrative DC – Dubai, UAE | J10: PO-SYN-7118 | K10: 2 | L10: =COUNTIF(Documents!$C$5:$C$83,A10) -> 2 | M10: Clean
A11: SYN-EM-007 | B11: SYN-SH-007 | C11: 2026-09-03 08:14 | D11: shipping@greenleaf.example | E11: RE: Dispatch confirmation PO PO-SYN-7121 | F11: SUP-005 | G11: =INDEX(Suppliers!$B$5:$B$12,MATCH(F11,Suppliers!$A$5:$A$12,0)) -> Greenleaf Foods JSC (fictional) | H11: Vietnam | I11: Illustrative DC – Dubai, UAE | J11: PO-SYN-7121 | K11: 3 | L11: =COUNTIF(Documents!$C$5:$C$83,A11) -> 3 | M11: Clean (scan quality issue)
A12: SYN-EM-008 | B12: SYN-SH-008 | C12: 2026-09-03 13:22 | D12: shipping@voltix.example | E12: FW: Shipping documents PO-SYN-7124 | F12: SUP-006 | G12: =INDEX(Suppliers!$B$5:$B$12,MATCH(F12,Suppliers!$A$5:$A$12,0)) -> Voltix Components Sdn Bhd (fictional) | H12: Malaysia | I12: Illustrative DC – Dubai, UAE | J12: PO-SYN-7124 | K12: 3 | L12: =COUNTIF(Documents!$C$5:$C$83,A12) -> 3 | M12: New SKU – Test Case B (Case 3)
A13: SYN-EM-009 | B13: SYN-SH-009 | C13: 2026-09-03 11:05 | D13: shipping@brightlink.example | E13: Docs attached – PO-SYN-7127 – ETA Dubai | F13: SUP-001 | G13: =INDEX(Suppliers!$B$5:$B$12,MATCH(F13,Suppliers!$A$5:$A$12,0)) -> Brightlink Electronics Co. (fictional) | H13: China | I13: Illustrative DC – Dubai, UAE | J13: PO-SYN-7127 | K13: 2 | L13: =COUNTIF(Documents!$C$5:$C$83,A13) -> 2 | M13: Description variation; UOM 'Pc' (Cases 2,6)
A14: SYN-EM-010 | B14: SYN-SH-010 | C14: 2026-09-04 16:45 | D14: shipping@everhome.example | E14: Docs attached – PO-SYN-7130 – ETA Dubai | F14: SUP-002 | G14: =INDEX(Suppliers!$B$5:$B$12,MATCH(F14,Suppliers!$A$5:$A$12,0)) -> Everhome Housewares Ltd (fictional) | H14: China | I14: Illustrative DC – Dubai, UAE | J14: PO-SYN-7130 | K14: 3 | L14: =COUNTIF(Documents!$C$5:$C$83,A14) -> 3 | M14: Clean
A15: SYN-EM-011 | B15: SYN-SH-011 | C15: 2026-09-04 16:45 | D15: shipping@brightlink.example | E15: ASN / Packing list & invoice for PO PO-SYN-7133 | F15: SUP-001 | G15: =INDEX(Suppliers!$B$5:$B$12,MATCH(F15,Suppliers!$A$5:$A$12,0)) -> Brightlink Electronics Co. (fictional) | H15: China | I15: Illustrative DC – Dubai, UAE | J15: PO-SYN-7133 | K15: 3 | L15: =COUNTIF(Documents!$C$5:$C$83,A15) -> 3 | M15: Ambiguous SKU – Test Case C (Case 4)
A16: SYN-EM-012 | B16: SYN-SH-012 | C16: 2026-09-04 08:14 | D16: shipping@anka.example | E16: Docs attached – PO-SYN-7136 – ETA Dubai | F16: SUP-004 | G16: =INDEX(Suppliers!$B$5:$B$12,MATCH(F16,Suppliers!$A$5:$A$12,0)) -> Anka Accessories Trading (fictional) | H16: Turkey | I16: Illustrative DC – Dubai, UAE | J16: PO-SYN-7136 | K16: 3 | L16: =COUNTIF(Documents!$C$5:$C$83,A16) -> 3 | M16: Clean (scanned COO)
... A34: SYN-EM-030 | B34: SYN-SH-030 | C34: 2026-09-14 11:05 | D34: shipping@desertpalm.example | E34: FW: Shipping documents PO-SYN-7190 | F34: SUP-007 | G34: =INDEX(Suppliers!$B$5:$B$12,MATCH(F34,Suppliers!$A$5:$A$12,0)) -> Desert Palm Foodstuff Trading LLC (fictional) | H34: UAE | I34: Illustrative DC – Dubai, UAE | J34: PO-SYN-7190 | K34: 3 | L34: =COUNTIF(Documents!$C$5:$C$83,A34) -> 3 | M34: Clean

Sheet Documents
A1: ⚠ Synthetic data — created solely for POC demonstration. Not Transworld data. All suppliers, SKUs, shipments, emails and documents are fictional.
A2: STEP 2b – Table B: Documents / Attachments (79) with classification ground truth
A3: Column colours: Dark blue = data as received (input) | Green = GROUND TRUTH (known correct answer) | Blue = SIMULATED AI OUTPUT | Orange = TEST RESULT (formula: AI vs ground truth)
A4: Doc_ID | B4: Shipment_ID | C4: Email_ID | D4: File_Name (as received) | E4: Pages | F4: Doc_Total_Gross_Weight (kg) | G4: GT_Document_Type | H4: GT_Relevant | I4: GT_Completeness | J4: AI_Document_Type | K4: AI_Class_Confidence | L4: AI_Action | M4: Classification_Correct (1/0)
A5: SYN-PL-001 | B5: SYN-SH-001 | C5: SYN-EM-001 | D5: Packing_List_4401.pdf | E5: 2 | F5: 945 | G5: Packing List | H5: Yes | I5: Complete | J5: Packing List | K5: 0.94 | L5: =IF(K5<Decision_Rules!$C$5,"Human confirm","Auto") -> Auto | M5: =IF(G5=J5,1,0) -> 1
A6: SYN-CI-001 | B6: SYN-SH-001 | C6: SYN-EM-001 | D6: CI 7701.pdf | E6: 1 | F6: 945 | G6: Commercial Invoice | H6: Yes | I6: Complete | J6: Commercial Invoice | K6: 0.96 | L6: =IF(K6<Decision_Rules!$C$5,"Human confirm","Auto") -> Auto | M6: =IF(G6=J6,1,0) -> 1
A7: SYN-COO-001 | B7: SYN-SH-001 | C7: SYN-EM-001 | D7: Certificate_of_Origin_001.pdf | E7: 1 | G7: Certificate of Origin | H7: Yes | I7: Complete | J7: Certificate of Origin | K7: 0.99 | L7: =IF(K7<Decision_Rules!$C$5,"Human confirm","Auto") -> Auto | M7: =IF(G7=J7,1,0) -> 1
A8: SYN-PL-002 | B8: SYN-SH-002 | C8: SYN-EM-002 | D8: Packing_List_4402.pdf | E8: 1 | F8: 2548 | G8: Packing List | H8: Yes | I8: Complete | J8: Packing List | K8: 0.99 | L8: =IF(K8<Decision_Rules!$C$5,"Human confirm","Auto") -> Auto | M8: =IF(G8=J8,1,0) -> 1
A9: SYN-CI-002 | B9: SYN-SH-002 | C9: SYN-EM-002 | D9: Invoice_7702.pdf | E9: 1 | F9: 2548 | G9: Commercial Invoice | H9: Yes | I9: Complete | J9: Commercial Invoice | K9: 0.95 | L9: =IF(K9<Decision_Rules!$C$5,"Human confirm","Auto") -> Auto | M9: =IF(G9=J9,1,0) -> 1
A10: SYN-PL-003 | B10: SYN-SH-003 | C10: SYN-EM-003 | D10: Packing_List_4403.pdf | E10: 2 | F10: 175 | G10: Packing List | H10: Yes | I10: Complete | J10: Packing List | K10: 0.98 | L10: =IF(K10<Decision_Rules!$C$5,"Human confirm","Auto") -> Auto | M10: =IF(G10=J10,1,0) -> 1
A11: SYN-CI-003 | B11: SYN-SH-003 | C11: SYN-EM-003 | D11: Invoice_7703.pdf | E11: 1 | F11: 175 | G11: Commercial Invoice | H11: Yes | I11: Complete | J11: Commercial Invoice | K11: 0.97 | L11: =IF(K11<Decision_Rules!$C$5,"Human confirm","Auto") -> Auto | M11: =IF(G11=J11,1,0) -> 1
A12: SYN-PL-004 | B12: SYN-SH-004 | C12: SYN-EM-004 | D12: Packing_List_4404.pdf | E12: 2 | F12: 196.8 | G12: Packing List | H12: Yes | I12: Complete | J12: Packing List | K12: 0.94 | L12: =IF(K12<Decision_Rules!$C$5,"Human confirm","Auto") -> Auto | M12: =IF(G12=J12,1,0) -> 1
A13: SYN-CI-004 | B13: SYN-SH-004 | C13: SYN-EM-004 | D13: Invoice_7704.pdf | E13: 1 | F13: 196.8 | G13: Commercial Invoice | H13: Yes | I13: Complete | J13: Commercial Invoice | K13: 0.95 | L13: =IF(K13<Decision_Rules!$C$5,"Human confirm","Auto") -> Auto | M13: =IF(G13=J13,1,0) -> 1
A14: SYN-COO-004 | B14: SYN-SH-004 | C14: SYN-EM-004 | D14: Certificate_of_Origin_004.pdf | E14: 1 | G14: Certificate of Origin | H14: Yes | I14: Complete | J14: Certificate of Origin | K14: 0.96 | L14: =IF(K14<Decision_Rules!$C$5,"Human confirm","Auto") -> Auto | M14: =IF(G14=J14,1,0) -> 1
A15: SYN-PL-005 | B15: SYN-SH-005 | C15: SYN-EM-005 | D15: Packing_List_4405.pdf | E15: 2 | F15: 3895 | G15: Packing List | H15: Yes | I15: Complete | J15: Packing List | K15: 0.98 | L15: =IF(K15<Decision_Rules!$C$5,"Human confirm","Auto") -> Auto | M15: =IF(G15=J15,1,0) -> 1
A16: SYN-CI-005 | B16: SYN-SH-005 | C16: SYN-EM-005 | D16: CI 7705.pdf | E16: 1 | F16: 3895 | G16: Commercial Invoice | H16: Yes | I16: Complete | J16: Commercial Invoice | K16: 0.97 | L16: =IF(K16<Decision_Rules!$C$5,"Human confirm","Auto") -> Auto | M16: =IF(G16=J16,1,0) -> 1
A17: SYN-BOE-005 | B17: SYN-SH-005 | C17: SYN-EM-005 | D17: BOE_2026090005.pdf | E17: 2 | G17: Bill of Entry | H17: Yes | I17: Complete | J17: Bill of Entry | K17: 0.97 | L17: =IF(K17<Decision_Rules!$C$5,"Human confirm","Auto") -> Auto | M17: =IF(G17=J17,1,0) -> 1
A18: SYN-OTH-005 | B18: SYN-SH-005 | C18: SYN-EM-005 | D18: Company_Newsletter_Sep.pdf | E18: 4 | G18: Not Relevant | H18: No | I18: n/a | J18: Not Relevant | K18: 0.93 | L18: =IF(K18<Decision_Rules!$C$5,"Human confirm","Auto") -> Auto | M18: =IF(G18=J18,1,0) -> 1
A19: SYN-PL-006 | B19: SYN-SH-006 | C19: SYN-EM-006 | D19: Packing_List_4406.pdf | E19: 1 | F19: 900 | G19: Packing List | H19: Yes | I19: Complete | J19: Packing List | K19: 0.98 | L19: =IF(K19<Decision_Rules!$C$5,"Human confirm","Auto") -> Auto | M19: =IF(G19=J19,1,0) -> 1
A20: SYN-CI-006 | B20: SYN-SH-006 | C20: SYN-EM-006 | D20: Commercial Invoice 7706.pdf | E20: 1 | F20: 900 | G20: Commercial Invoice | H20: Yes | I20: Complete | J20: Commercial Invoice | K20: 0.95 | L20: =IF(K20<Decision_Rules!$C$5,"Human confirm","Auto") -> Auto | M20: =IF(G20=J20,1,0) -> 1
A21: SYN-PL-007 | B21: SYN-SH-007 | C21: SYN-EM-007 | D21: PL-4407.pdf | E21: 2 | F21: 474 | G21: Packing List | H21: Yes | I21: Complete | J21: Packing List | K21: 0.96 | L21: =IF(K21<Decision_Rules!$C$5,"Human confirm","Auto") -> Auto | M21: =IF(G21=J21,1,0) -> 1
A22: SYN-CI-007 | B22: SYN-SH-007 | C22: SYN-EM-007 | D22: Invoice_7707.pdf | E22: 1 | F22: 474 | G22: Commercial Invoice | H22: Yes | I22: Complete | J22: Commercial Invoice | K22: 0.95 | L22: =IF(K22<Decision_Rules!$C$5,"Human confirm","Auto") -> Auto | M22: =IF(G22=J22,1,0) -> 1
A23: SYN-COO-007 | B23: SYN-SH-007 | C23: SYN-EM-007 | D23: Certificate_of_Origin_007.pdf | E23: 1 | G23: Certificate of Origin | H23: Yes | I23: Complete | J23: Certificate of Origin | K23: 0.99 | L23: =IF(K23<Decision_Rules!$C$5,"Human confirm","Auto") -> Auto | M23: =IF(G23=J23,1,0) -> 1
A24: SYN-PL-008 | B24: SYN-SH-008 | C24: SYN-EM-008 | D24: Packing_List_4408.pdf | E24: 1 | F24: 293 | G24: Packing List | H24: Yes | I24: Complete | J24: Packing List | K24: 0.94 | L24: =IF(K24<Decision_Rules!$C$5,"Human confirm","Auto") -> Auto | M24: =IF(G24=J24,1,0) -> 1
A25: SYN-CI-008 | B25: SYN-SH-008 | C25: SYN-EM-008 | D25: CI 7708.pdf | E25: 1 | F25: 293 | G25: Commercial Invoice | H25: Yes | I25: Complete | J25: Commercial Invoice | K25: 0.99 | L25: =IF(K25<Decision_Rules!$C$5,"Human confirm","Auto") -> Auto | M25: =IF(G25=J25,1,0) -> 1
A26: SYN-COO-008 | B26: SYN-SH-008 | C26: SYN-EM-008 | D26: Certificate_of_Origin_008.pdf | E26: 1 | G26: Certificate of Origin | H26: Yes | I26: Complete | J26: Certificate of Origin | K26: 0.98 | L26: =IF(K26<Decision_Rules!$C$5,"Human confirm","Auto") -> Auto | M26: =IF(G26=J26,1,0) -> 1
A27: SYN-PL-009 | B27: SYN-SH-009 | C27: SYN-EM-009 | D27: packinglist 4409.pdf | E27: 1 | F27: 118 | G27: Packing List | H27: Yes | I27: Complete | J27: Packing List | K27: 0.95 | L27: =IF(K27<Decision_Rules!$C$5,"Human confirm","Auto") -> Auto | M27: =IF(G27=J27,1,0) -> 1
A28: SYN-CI-009 | B28: SYN-SH-009 | C28: SYN-EM-009 | D28: CI 7709.pdf | E28: 1 | F28: 118 | G28: Commercial Invoice | H28: Yes | I28: Complete | J28: Commercial Invoice | K28: 0.98 | L28: =IF(K28<Decision_Rules!$C$5,"Human confirm","Auto") -> Auto | M28: =IF(G28=J28,1,0) -> 1
A29: SYN-PL-010 | B29: SYN-SH-010 | C29: SYN-EM-010 | D29: Packing_List_4410.pdf | E29: 2 | F29: 782.5 | G29: Packing List | H29: Yes | I29: Complete | J29: Packing List | K29: 0.97 | L29: =IF(K29<Decision_Rules!$C$5,"Human confirm","Auto") -> Auto | M29: =IF(G29=J29,1,0) -> 1
A30: SYN-CI-010 | B30: SYN-SH-010 | C30: SYN-EM-010 | D30: Commercial Invoice 7710.pdf | E30: 1 | F30: 782.5 | G30: Commercial Invoice | H30: Yes | I30: Complete | J30: Commercial Invoice | K30: 0.96 | L30: =IF(K30<Decision_Rules!$C$5,"Human confirm","Auto") -> Auto | M30: =IF(G30=J30,1,0) -> 1
A31: SYN-BOE-010 | B31: SYN-SH-010 | C31: SYN-EM-010 | D31: BOE_2026090010.pdf | E31: 2 | G31: Bill of Entry | H31: Yes | I31: Complete | J31: Bill of Entry | K31: 0.97 | L31: =IF(K31<Decision_Rules!$C$5,"Human confirm","Auto") -> Auto | M31: =IF(G31=J31,1,0) -> 1
A32: SYN-PL-011 | B32: SYN-SH-011 | C32: SYN-EM-011 | D32: packinglist 4411.pdf | E32: 1 | F32: 1495 | G32: Packing List | H32: Yes | I32: Complete | J32: Packing List | K32: 0.99 | L32: =IF(K32<Decision_Rules!$C$5,"Human confirm","Auto") -> Auto | M32: =IF(G32=J32,1,0) -> 1
A33: SYN-CI-011 | B33: SYN-SH-011 | C33: SYN-EM-011 | D33: CI 7711.pdf | E33: 1 | F33: 1495 | G33: Commercial Invoice | H33: Yes | I33: Complete | J33: Commercial Invoice | K33: 0.94 | L33: =IF(K33<Decision_Rules!$C$5,"Human confirm","Auto") -> Auto | M33: =IF(G33=J33,1,0) -> 1
A34: SYN-COO-011 | B34: SYN-SH-011 | C34: SYN-EM-011 | D34: Certificate_of_Origin_011.pdf | E34: 1 | G34: Certificate of Origin | H34: Yes | I34: Complete | J34: Certificate of Origin | K34: 0.97 | L34: =IF(K34<Decision_Rules!$C$5,"Human confirm","Auto") -> Auto | M34: =IF(G34=J34,1,0) -> 1
A35: SYN-PL-012 | B35: SYN-SH-012 | C35: SYN-EM-012 | D35: packinglist 4412.pdf | E35: 1 | F35: 60.3 | G35: Packing List | H35: Yes | I35: Complete | J35: Packing List | K35: 0.98 | L35: =IF(K35<Decision_Rules!$C$5,"Human confirm","Auto") -> Auto | M35: =IF(G35=J35,1,0) -> 1
A36: SYN-CI-012 | B36: SYN-SH-012 | C36: SYN-EM-012 | D36: Commercial Invoice 7712.pdf | E36: 1 | F36: 60.3 | G36: Commercial Invoice | H36: Yes | I36: Complete | J36: Commercial Invoice | K36: 0.98 | L36: =IF(K36<Decision_Rules!$C$5,"Human confirm","Auto") -> Auto | M36: =IF(G36=J36,1,0) -> 1
A37: SYN-COO-012 | B37: SYN-SH-012 | C37: SYN-EM-012 | D37: scan_0912.pdf | E37: 1 | G37: Certificate of Origin | H37: Yes | I37: Complete | J37: Commercial Invoice | K37: 0.66 | L37: =IF(K37<Decision_Rules!$C$5,"Human confirm","Auto") -> Human confirm | M37: =IF(G37=J37,1,0) -> 0
A38: SYN-PL-013 | B38: SYN-SH-013 | C38: SYN-EM-013 | D38: packinglist 4413.pdf | E38: 2 | F38: 403 | G38: Packing List | H38: Yes | I38: Incomplete – quantity blank on 1 line | J38: Packing List | K38: 0.96 | L38: =IF(K38<Decision_Rules!$C$5,"Human confirm","Auto") -> Auto | M38: =IF(G38=J38,1,0) -> 1
A39: SYN-CI-013 | B39: SYN-SH-013 | C39: SYN-EM-013 | D39: Commercial Invoice 7713.pdf | E39: 1 | F39: 403 | G39: Commercial Invoice | H39: Yes | I39: Complete | J39: Commercial Invoice | K39: 0.95 | L39: =IF(K39<Decision_Rules!$C$5,"Human confirm","Auto") -> Auto | M39: =IF(G39=J39,1,0) -> 1
A40: SYN-PL-014 | B40: SYN-SH-014 | C40: SYN-EM-014 | D40: Packing_List_4414.pdf | E40: 1 | F40: 350 | G40: Packing List | H40: Yes | I40: Complete | J40: Packing List | K40: 0.98 | L40: =IF(K40<Decision_Rules!$C$5,"Human confirm","Auto") -> Auto | M40: =IF(G40=J40,1,0) -> 1
...

Sheet Line_Items
A1: ⚠ Synthetic data — created solely for POC demonstration. Not Transworld data. All suppliers, SKUs, shipments, emails and documents are fictional.
A2: STEP 2c – Table C: Document Line Items (103) with ground truth, simulated AI output and test result
A3: Column colours: Dark blue = data as received (input) | Green = GROUND TRUTH (known correct answer) | Blue = SIMULATED AI OUTPUT | Orange = TEST RESULT (formula: AI vs ground truth) | AC3: Extraction_Correct = 1 if SKU code, description, qty, UOM, HS code, origin and weight were all read exactly as printed (field-level check done during test). Blue = test input.
A4: Line_ID | B4: Shipment_ID | C4: Source_Doc_ID | D4: Line_No | E4: SKU_ID_from_document | F4: Product_Description (as on document) | G4: Quantity | H4: UOM (as received) | I4: HS_Code | J4: Country_of_Origin | K4: Weight (kg) | L4: Invoice_Quantity (cross-check) | M4: GT_SKU_Status | N4: GT_Matched_SKU | O4: GT_Normalised_UOM | P4: GT_Validation | Q4: GT_Note | R4: AI_Extracted_Qty | S4: AI_SKU_Status | T4: AI_Matched_SKU | U4: AI_Normalised_UOM | V4: AI_Confidence | W4: AI_Validation | X4: AI_Route | Y4: AI_Reasoning (plain English) | Z4: SKU_Decision_Correct | AA4: Validation_Correct | AB4: UOM_Norm_Correct | AC4: Extraction_Correct
A5: SYN-LN-001 | B5: SYN-SH-001 | C5: SYN-PL-001 | D5: 1 | E5: EL-4105 | F5: Bluetooth Speaker 10W Portable | G5: 600 | H5: PCS | I5: 8518.22 | J5: China | K5: 330 | L5: 600 | M5: Existing | N5: EL-4105 | O5: PCS | P5: Valid | Q5: Exact match | R5: 600 | S5: Existing | T5: EL-4105 | U5: PCS | V5: 0.95 | W5: Valid | X5: =IF(S5="New","Human approval (new SKU)",IF(OR(S5<>"Existing",W5<>"Valid",V5<Decision_Rules!$C$6),"Human review","Auto-processed")) -> Auto-processed | Y5: Exact SKU code and description match | Z5: =IF(M5=S5,1,0) -> 1 | AA5: =IF(P5=W5,1,0) -> 1 | AB5: =IF(O5=U5,1,0) -> 1 | AC5: 1
A6: SYN-LN-002 | B6: SYN-SH-001 | C6: SYN-PL-001 | D6: 2 | E6: EL-4230 | F6: LED Strip Light 5m RGB | G6: 150 | H6: PCS | I6: 9405.42 | J6: China | K6: 45 | L6: 150 | M6: Existing | N6: EL-4230 | O6: PCS | P6: Valid | Q6: Exact match | R6: 150 | S6: Existing | T6: EL-4230 | U6: PCS | V6: 0.99 | W6: Valid | X6: =IF(S6="New","Human approval (new SKU)",IF(OR(S6<>"Existing",W6<>"Valid",V6<Decision_Rules!$C$6),"Human review","Auto-processed")) -> Auto-processed | Y6: Exact SKU code and description match | Z6: =IF(M6=S6,1,0) -> 1 | AA6: =IF(P6=W6,1,0) -> 1 | AB6: =IF(O6=U6,1,0) -> 1 | AC6: 1
A7: SYN-LN-003 | B7: SYN-SH-001 | C7: SYN-PL-001 | D7: 3 | E7: EL-4220 | F7: LED Desk Lamp with USB Port | G7: 500 | H7: PCS | I7: 9405.21 | J7: China | K7: 450 | L7: 500 | M7: Existing | N7: EL-4220 | O7: PCS | P7: Valid | Q7: Exact match | R7: 500 | S7: Existing | T7: EL-4220 | U7: PCS | V7: 0.95 | W7: Valid | X7: =IF(S7="New","Human approval (new SKU)",IF(OR(S7<>"Existing",W7<>"Valid",V7<Decision_Rules!$C$6),"Human review","Auto-processed")) -> Auto-processed | Y7: Exact SKU code and description match | Z7: =IF(M7=S7,1,0) -> 1 | AA7: =IF(P7=W7,1,0) -> 1 | AB7: =IF(O7=U7,1,0) -> 1 | AC7: 1
A8: SYN-LN-004 | B8: SYN-SH-001 | C8: SYN-PL-001 | D8: 4 | E8: EL-4110 | F8: Wireless Earbuds - True Wireless, Black | G8: 1000 | H8: PCS | I8: 8518.30 | J8: China | K8: 120 | L8: 1000 | M8: Existing | N8: EL-4110 | O8: PCS | P8: Valid | Q8: Exact match | R8: 1000 | S8: Existing | T8: EL-4110 | U8: PCS | V8: 0.98 | W8: Valid | X8: =IF(S8="New","Human approval (new SKU)",IF(OR(S8<>"Existing",W8<>"Valid",V8<Decision_Rules!$C$6),"Human review","Auto-processed")) -> Auto-processed | Y8: Exact SKU code and description match | Z8: =IF(M8=S8,1,0) -> 1 | AA8: =IF(P8=W8,1,0) -> 1 | AB8: =IF(O8=U8,1,0) -> 1 | AC8: 1
A9: SYN-LN-005 | B9: SYN-SH-002 | C9: SYN-PL-002 | D9: 1 | E9: CG-3102 | F9: Dumbbell Pair 5kg | G9: 240 | H9: SET | I9: 9506.91 | J9: India | K9: 2448 | L9: 240 | M9: Existing | N9: CG-3102 | O9: SET | P9: Valid | Q9: Exact match | R9: 240 | S9: Existing | T9: CG-3102 | U9: SET | V9: 0.99 | W9: Valid | X9: =IF(S9="New","Human approval (new SKU)",IF(OR(S9<>"Existing",W9<>"Valid",V9<Decision_Rules!$C$6),"Human review","Auto-processed")) -> Auto-processed | Y9: Exact SKU code and description match | Z9: =IF(M9=S9,1,0) -> 1 | AA9: =IF(P9=W9,1,0) -> 1 | AB9: =IF(O9=U9,1,0) -> 1 | AC9: 1
A10: SYN-LN-006 | B10: SYN-SH-002 | C10: SYN-PL-002 | D10: 2 | E10: CG-3501 | F10: A5 Notebook Ruled 200p | G10: 200 | H10: PCS | I10: 4820.10 | J10: India | K10: 60 | L10: 200 | M10: Existing | N10: CG-3501 | O10: PCS | P10: Valid | Q10: Exact match | R10: 200 | S10: Existing | T10: CG-3501 | U10: PCS | V10: 0.99 | W10: Valid | X10: =IF(S10="New","Human approval (new SKU)",IF(OR(S10<>"Existing",W10<>"Valid",V10<Decision_Rules!$C$6),"Human review","Auto-processed")) -> Auto-processed | Y10: Exact SKU code and description match | Z10: =IF(M10=S10,1,0) -> 1 | AA10: =IF(P10=W10,1,0) -> 1 | AB10: =IF(O10=U10,1,0) -> 1 | AC10: 1
A11: SYN-LN-007 | B11: SYN-SH-002 | C11: SYN-PL-002 | D11: 3 | E11: CG-3301 | F11: Eau de Parfum 100ml | G11: 100 | H11: PCS | I11: 3303.00 | J11: India | K11: 40 | L11: 100 | M11: Existing | N11: CG-3301 | O11: PCS | P11: Valid | Q11: Exact match | R11: 100 | S11: Existing | T11: CG-3301 | U11: PCS | V11: 0.98 | W11: Valid | X11: =IF(S11="New","Human approval (new SKU)",IF(OR(S11<>"Existing",W11<>"Valid",V11<Decision_Rules!$C$6),"Human review","Auto-processed")) -> Auto-processed | Y11: Exact SKU code and description match | Z11: =IF(M11=S11,1,0) -> 1 | AA11: =IF(P11=W11,1,0) -> 1 | AB11: =IF(O11=U11,1,0) -> 1 | AC11: 1
A12: SYN-LN-008 | B12: SYN-SH-003 | C12: SYN-PL-003 | D12: 1 | E12: AC-2201 | F12: USB-C to USB-C Cable 1m | G12: 200 | H12: Pieces | I12: 8544.42 | J12: Malaysia | K12: 10 | L12: 200 | M12: Existing | N12: AC-2201 | O12: PCS | P12: Valid | Q12: Exact match; UOM 'Pieces' normalised to PCS | R12: 200 | S12: Existing | T12: AC-2201 | U12: PCS | V12: 0.98 | W12: Valid | X12: =IF(S12="New","Human approval (new SKU)",IF(OR(S12<>"Existing",W12<>"Valid",V12<Decision_Rules!$C$6),"Human review","Auto-processed")) -> Auto-processed | Y12: Exact match; UOM normalised. NOTE: HS code mis-read as 8544.49 (not caught) | Z12: =IF(M12=S12,1,0) -> 1 | AA12: =IF(P12=W12,1,0) -> 1 | AB12: =IF(O12=U12,1,0) -> 1 | AC12: 0
A13: SYN-LN-009 | B13: SYN-SH-003 | C13: SYN-PL-003 | D13: 2 | E13: EL-4301 | F13: Power Bank 10000mAh | G13: 500 | H13: Pieces | I13: 8507.60 | J13: Malaysia | K13: 125 | L13: 500 | M13: Existing | N13: EL-4301 | O13: PCS | P13: Valid | Q13: Exact match; UOM 'Pieces' normalised to PCS | R13: 500 | S13: Existing | T13: EL-4301 | U13: PCS | V13: 0.99 | W13: Valid | X13: =IF(S13="New","Human approval (new SKU)",IF(OR(S13<>"Existing",W13<>"Valid",V13<Decision_Rules!$C$6),"Human review","Auto-processed")) -> Auto-processed | Y13: Exact match; UOM 'Pieces'→PCS | Z13: =IF(M13=S13,1,0) -> 1 | AA13: =IF(P13=W13,1,0) -> 1 | AB13: =IF(O13=U13,1,0) -> 1 | AC13: 1
A14: SYN-LN-010 | B14: SYN-SH-003 | C14: SYN-PL-003 | D14: 3 | E14: EL-4402 | F14: Wireless Optical Mouse | G14: 400 | H14: Pieces | I14: 8471.60 | J14: Malaysia | K14: 40 | L14: 400 | M14: Existing | N14: EL-4402 | O14: PCS | P14: Valid | Q14: Exact match; UOM 'Pieces' normalised to PCS | R14: 400 | S14: Existing | T14: EL-4402 | U14: PCS | V14: 0.97 | W14: Valid | X14: =IF(S14="New","Human approval (new SKU)",IF(OR(S14<>"Existing",W14<>"Valid",V14<Decision_Rules!$C$6),"Human review","Auto-processed")) -> Auto-processed | Y14: Exact match; UOM 'Pieces'→PCS | Z14: =IF(M14=S14,1,0) -> 1 | AA14: =IF(P14=W14,1,0) -> 1 | AB14: =IF(O14=U14,1,0) -> 1 | AC14: 1
A15: SYN-LN-011 | B15: SYN-SH-004 | C15: SYN-PL-004 | D15: 1 | E15: EL-4001 | F15: Wireless Router AX1800 | G15: 100 | H15: PCS | I15: 8517.62 | J15: China | K15: 120 | L15: 100 | M15: Existing | N15: EL-4001 | O15: PCS | P15: Valid | Q15: Exact match | R15: 100 | S15: Existing | T15: EL-4001 | U15: PCS | V15: 0.98 | W15: Valid | X15: =IF(S15="New","Human approval (new SKU)",IF(OR(S15<>"Existing",W15<>"Valid",V15<Decision_Rules!$C$6),"Human review","Auto-processed")) -> Auto-processed | Y15: Exact SKU code and description match | Z15: =IF(M15=S15,1,0) -> 1 | AA15: =IF(P15=W15,1,0) -> 1 | AB15: =IF(O15=U15,1,0) -> 1 | AC15: 1
A16: SYN-LN-012 | B16: SYN-SH-004 | C16: SYN-PL-004 | D16: 2 | E16: EL-4110 | F16: Wireless Earbuds TWS Blk | G16: 240 | H16: PCS | I16: 8518.30 | J16: China | K16: 28.8 | L16: 240 | M16: Existing | N16: EL-4110 | O16: PCS | P16: Valid | Q16: Existing SKU; abbreviated description | R16: 240 | S16: Existing | T16: EL-4110 | U16: PCS | V16: 0.93 | W16: Valid | X16: =IF(S16="New","Human approval (new SKU)",IF(OR(S16<>"Existing",W16<>"Valid",V16<Decision_Rules!$C$6),"Human review","Auto-processed")) -> Auto-processed | Y16: SKU code exact; description 88% similar (abbreviation) → Existing | Z16: =IF(M16=S16,1,0) -> 1 | AA16: =IF(P16=W16,1,0) -> 1 | AB16: =IF(O16=U16,1,0) -> 1 | AC16: 1
... A47: SYN-LN-043 | B47: SYN-SH-013 | C47: SYN-PL-013 | D47: 1 | E47: CG-3101 | F47: Yoga Mat 6mm | G47: 100 | H47: PCS | I47: 9506.91 | J47: India | K47: 100 | L47: 100 | M47: Existing | N47: CG-3101 | O47: PCS | P47: Valid | Q47: Exact match | R47: 100 | S47: Existing | T47: CG-3101 | U47: PCS | V47: 0.99 | W47: Valid | X47: =IF(S47="New","Human approval (new SKU)",IF(OR(S47<>"Existing",W47<>"Valid",V47<Decision_Rules!$C$6),"Human review","Auto-processed")) -> Auto-processed | Y47: Exact SKU code and description match | Z47: =IF(M47=S47,1,0) -> 1 | AA47: =IF(P47=W47,1,0) -> 1 | AB47: =IF(O47=U47,1,0) -> 1 | AC47: 1
A48: SYN-LN-044 | B48: SYN-SH-013 | C48: SYN-PL-013 | D48: 2 | E48: CG-3210 | F48: Hair Dryer 1800W | H48: PCS | I48: 8516.31 | J48: India | K48: 168 | L48: 240 | M48: Existing | N48: CG-3210 | O48: PCS | P48: Missing Field | Q48: Quantity missing on Packing List | S48: Existing | T48: CG-3210 | U48: PCS | V48: 0.97 | W48: Missing Field | X48: =IF(S48="New","Human approval (new SKU)",IF(OR(S48<>"Existing",W48<>"Valid",V48<Decision_Rules!$C$6),"Human review","Auto-processed")) -> Human review | Y48: Existing SKU; mandatory field Quantity blank on Packing List | Z48: =IF(M48=S48,1,0) -> 1 | AA48: =IF(P48=W48,1,0) -> 1 | AB48: =IF(O48=U48,1,0) -> 1 | AC48: 1
A49: SYN-LN-045 | B49: SYN-SH-013 | C49: SYN-PL-013 | D49: 3 | E49: CG-3330 | F49: Shampoo 400ml | G49: 300 | H49: PCS | I49: 3305.10 | J49: India | K49: 135 | L49: 300 | M49: Existing | N49: CG-3330 | O49: PCS | P49: Valid | Q49: Exact match | R49: 300 | S49: Existing | T49: CG-3330 | U49: PCS | V49: 0.98 | W49: Valid | X49: =IF(S49="New","Human approval (new SKU)",IF(OR(S49<>"Existing",W49<>"Valid",V49<Decision_Rules!$C$6),"Human review","Auto-processed")) -> Auto-processed | Y49: Exact SKU code and description match | Z49: =IF(M49=S49,1,0) -> 1 | AA49: =IF(P49=W49,1,0) -> 1 | AB49: =IF(O49=U49,1,0) -> 1 | AC49: 1
A50: SYN-LN-046 | B50: SYN-SH-014 | C50: SYN-PL-014 | D50: 1 | E50: CG-3O05 | F50: Stainless Steel Water Bottle 750ml | G50: 400 | H50: pcs | I50: 7323.93 | J50: India | K50: 140 | L50: 400 | M50: Existing | N50: CG-3005 | O50: PCS | P50: Valid | Q50: Typo: letter 'O' for zero; full description unique | R50: 400 | S50: Existing | T50: CG-3005 | U50: PCS | V50: 0.91 | W50: Valid | X50: =IF(S50="New","Human approval (new SKU)",IF(OR(S50<>"Existing",W50<>"Valid",V50<Decision_Rules!$C$6),"Human review","Auto-processed")) -> Auto-processed | Y50: Code corrected CG-3O05→CG-3005: 1-char difference + description 100% + same supplier. Correction logged | Z50: =IF(M50=S50,1,0) -> 1 | AA50: =IF(P50=W50,1,0) -> 1 | AB50: =IF(O50=U50,1,0) -> 1 | AC50: 1
A51: SYN-LN-047 | B51: SYN-SH-014 | C51: SYN-PL-014 | D51: 2 | E51: CG-3101 | F51: Yoga Mat 6mm | G51: 120 | H51: pcs | I51: 9506.91 | J51: India | K51: 120 | L51: 120 | M51: Existing | N51: CG-3101 | O51: PCS | P51: Valid | Q51: Exact match; UOM 'pcs' normalised | R51: 120 | S51: Existing | T51: CG-3101 | U51: PCS | V51: 0.95 | W51: Valid | X51: =IF(S51="New","Human approval (new SKU)",IF(OR(S51<>"Existing",W51<>"Valid",V51<Decision_Rules!$C$6),"Human review","Auto-processed")) -> Auto-processed | Y51: Exact match; UOM 'pcs'→PCS | Z51: =IF(M51=S51,1,0) -> 1 | AA51: =IF(P51=W51,1,0) -> 1 | AB51: =IF(O51=U51,1,0) -> 1 | AC51: 1
A52: SYN-LN-048 | B52: SYN-SH-014 | C52: SYN-PL-014 | D52: 3 | E52: CG-3330 | F52: Shampoo 400ml | G52: 200 | H52: pcs | I52: 3305.10 | J52: India | K52: 90 | L52: 200 | M52: Existing | N52: CG-3330 | O52: PCS | P52: Valid | Q52: Exact match; UOM 'pcs' normalised | R52: 200 | S52: Existing | T52: CG-3330 | U52: PCS | V52: 0.97 | W52: Valid | X52: =IF(S52="New","Human approval (new SKU)",IF(OR(S52<>"Existing",W52<>"Valid",V52<Decision_Rules!$C$6),"Human review","Auto-processed")) -> Auto-processed | Y52: Exact match; UOM 'pcs'→PCS | Z52: =IF(M52=S52,1,0) -> 1 | AA52: =IF(P52=W52,1,0) -> 1 | AB52: =IF(O52=U52,1,0) -> 1 | AC52: 1
A53: SYN-LN-049 | B53: SYN-SH-015 | C53: SYN-PL-015 | D53: 1 | E53: HH-5501 | F53: Electric Kettle 1.7L Stainless | G53: 400 | H53: PCS | I53: 8516.71 | J53: Germany | K53: 520 | L53: 400 | M53: Existing | N53: HH-5501 | O53: PCS | P53: Valid | Q53: Exact match | R53: 400 | S53: Existing | T53: HH-5501 | U53: PCS | V53: 0.98 | W53: Valid | X53: =IF(S53="New","Human approval (new SKU)",IF(OR(S53<>"Existing",W53<>"Valid",V53<Decision_Rules!$C$6),"Human review","Auto-processed")) -> Auto-processed | Y53: Exact SKU code and description match | Z53: =IF(M53=S53,1,0) -> 1 | AA53: =IF(P53=W53,1,0) -> 1 | AB53: =IF(O53=U53,1,0) -> 1 | AC53: 1
A54: SYN-LN-050 | B54: SYN-SH-015 | C54: SYN-PL-015 | D54: 2 | E54: HH-5510 | F54: Steam Iron 2400W | G54: 300 | H54: PCS | I54: 8516.40 | J54: Germany | K54: 420 | L54: 300 | M54: Existing | N54: HH-5510 | O54: PCS | P54: Valid | Q54: Exact match | R54: 300 | S54: Existing | T54: HH-5510 | U54: PCS | V54: 0.98 | W54: Valid | X54: =IF(S54="New","Human approval (new SKU)",IF(OR(S54<>"Existing",W54<>"Valid",V54<Decision_Rules!$C$6),"Human review","Auto-processed")) -> Auto-processed | Y54: Exact SKU code and description match | Z54: =IF(M54=S54,1,0) -> 1 | AA54: =IF(P54=W54,1,0) -> 1 | AB54: =IF(O54=U54,1,0) -> 1 | AC54: 1
A55: SYN-LN-051 | B55: SYN-SH-015 | C55: SYN-PL-015 | D55: 3 | E55: HH-5520 | F55: Hand Blender 600W | G55: 120 | H55: PCS | I55: 8509.40 | J55: Germany | K55: 132 | L55: 120 | M55: Existing | N55: HH-5520 | O55: PCS | P55: Valid | Q55: Exact match | R55: 120 | S55: Existing | T55: HH-5520 | U55: PCS | V55: 0.98 | W55: Valid | X55: =IF(S55="New","Human approval (new SKU)",IF(OR(S55<>"Existing",W55<>"Valid",V55<Decision_Rules!$C$6),"Human review","Auto-processed")) -> Auto-processed | Y55: Exact SKU code and description match | Z55: =IF(M55=S55,1,0) -> 1 | AA55: =IF(P55=W55,1,0) -> 1 | AB55: =IF(O55=U55,1,0) -> 1 | AC55: 1
A56: SYN-LN-052 | B56: SYN-SH-016 | C56: SYN-PL-016 | D56: 1 | E56: HH-5120 | F56: Bamboo Chopping Board Large | G56: 150 | H56: PCS | I56: 4419.90 | J56: China | K56: 150 | M56: Existing | N56: HH-5120 | O56: PCS | P56: Valid | Q56: Exact match | R56: 150 | S56: Existing | T56: HH-5120 | U56: PCS | V56: 0.97 | W56: Valid | X56: =IF(S56="New","Human approval (new SKU)",IF(OR(S56<>"Existing",W56<>"Valid",V56<Decision_Rules!$C$6),"Human review","Auto-processed")) -> Auto-processed | Y56: Exact SKU code and description match | Z56: =IF(M56=S56,1,0) -> 1 | AA56: =IF(P56=W56,1,0) -> 1 | AB56: =IF(O56=U56,1,0) -> 1 | AC56: 1
A57: SYN-LN-053 | B57: SYN-SH-016 | C57: SYN-PL-016 | D57: 2 | E57: HH-5101 | F57: Non-Stick Frying Pan 28cm | G57: 200 | H57: PCS | I57: 7323.99 | J57: China | K57: 220 | M57: Existing | N57: HH-5101 | O57: PCS | P57: Valid | Q57: Exact match | R57: 200 | S57: Existing | T57: HH-5101 | U57: PCS | V57: 0.97 | W57: Valid | X57: =IF(S57="New","Human approval (new SKU)",IF(OR(S57<>"Existing",W57<>"Valid",V57<Decision_Rules!$C$6),"Human review","Auto-processed")) -> Auto-processed | Y57: Exact SKU code and description match | Z57: =IF(M57=S57,1,0) -> 1 | AA57: =IF(P57=W57,1,0) -> 1 | AB57: =IF(O57=U57,1,0) -> 1 | AC57: 1
A58: SYN-LN-054 | B58: SYN-SH-016 | C58: SYN-PL-016 | D58: 3 | E58: HH-5601 | F58: Vacuum Flask 1L | G58: 120 | H58: PCS | I58: 9617.00 | J58: China | K58: 72 | M58: Existing | N58: HH-5601 | O58: PCS | P58: Valid | Q58: Exact match | R58: 120 | S58: Existing | T58: HH-5601 | U58: PCS | V58: 0.96 | W58: Valid | X58: =IF(S58="New","Human approval (new SKU)",IF(OR(S58<>"Existing",W58<>"Valid",V58<Decision_Rules!$C$6),"Human review","Auto-processed")) -> Auto-processed | Y58: Exact SKU code and description match | Z58: =IF(M58=S58,1,0) -> 1 | AA58: =IF(P58=W58,1,0) -> 1 | AB58: =IF(O58=U58,1,0) -> 1 | AC58: 1
